Workbook

Sheet Toelichting
A1: Register digital twins voor het energiesysteem en de gebouwde omgeving
A2: Versie 12 · publieksversie · peildatum 21 oktober 2026 · opgesteld door M. van Glabbeek (Bizz4Mation) · Verkenner Digital Twins, Energy Innovation NL
A3: Publieksversie; geen officiële publicatie van Energy Innovation NL. Interne werkonderdelen voor de verdiepende gesprekken (analysekader ter bespreking, verdiepingsvoorstel, verificatielijst, scope en prioriteit) zijn weggelaten, net als samenvattingen van bronnen met een voorbehoud tegen tekst- en datamining of verwerking met AI. Begeleidend bestand bij het rapport 'Digital twins voor het energiesysteem en de gebouwde omgeving' (versie 12, publieksversie).
A5: Doel
A6: Het register brengt 146 digital-twin-initiatieven in Nederland, Europa en een beknopte selectie daarbuiten in kaart, met de kaders en bouwstenen waarop ze aansluiten en hun onderlinge relaties. Het is de basis voor het portfolio-overzicht van de verkenning, voor het prototype van een interactieve kaart en voor de verdiepende gesprekken met initiatiefnemers.
A8: Tabbladen
A9: - Portfolio: alle initiatieven met ordeningsvelden, bron, coördinaten en (blauw) afgeleide velden zoals genormaliseerd twinniveau, inzetniveau, betrouwbaarheid van de duiding en scopevoorstel.
A10: - Werkhypothesen: 29 hypothesen uit de horizontale analyse, met onderbouwing, initiatieven en zekerheid.
A11: - Kaders, Bouwstenen, Relaties en Aanbieders: de objecten waarnaar initiatieven verwijzen.
A12: - Analyse: tellingen met formules op het tabblad Portfolio (rijen 2 t/m 500); rekent mee als het portfolio wordt aangevuld.
A13: - Ordeningskader: de waarden per dimensie.
A14: - Referentiearchitectuur: de 52 componenten van de synthese-referentiearchitectuur (bijlage A van het rapport) per laag en band, met herkomst en voorbeeld-ID's, en het inzetspectrum.
... A45: Versiegeschiedenis
A46: Versie | B46: Datum | C46: Auteur | D46: Omschrijving
A47: 1 | B47: september 2026 | C47: M. van Glabbeek (Bizz4Mation) | D47: Eerste inventarisatie van digital-twin-initiatieven in Nederland en de EU voor de gebouwde omgeving en het energiedomein.
A48: 2 | B48: september 2026 | C48: M. van Glabbeek (Bizz4Mation) | D48: Inventarisatie aangevuld en herzien.
A49: 3 | B49: september 2026 | C49: M. van Glabbeek (Bizz4Mation) | D49: Breed register gebouwde omgeving en energie in een apart tabblad (Register GO).
A50: 4 | B50: oktober 2026 | C50: M. van Glabbeek (Bizz4Mation) | D50: Portfolio energie geordend naar rol, functie, schaal, twinniveau en volwassenheid; koppeling aan ADE, NPE, NEDRA en Europese kaders; uitwerking voor de concept-verkenning.
A51: 5 | B51: oktober 2026 | C51: M. van Glabbeek (Bizz4Mation) | D51: Zoekgebied verbreed naar EU-breed en een beknopte verkenning van VK, VS, Australië, Japan en Nieuw-Zeeland, conform de offerte van 7 oktober 2026; tabbladen Kaders, Bouwstenen, Relaties en Analyse; coördinaten; artikel van het Nationaal Expertisecentrum Woningbouw verwerkt.
A52: 6 | B52: oktober 2026 | C52: M. van Glabbeek (Bizz4Mation) | D52: Register GO samengevoegd met het portfolio (29 initiatieven toegevoegd); focus Kern/Rand vervangen door Energie, Energie + GO, GO en Overig; rapport en register op hetzelfde versienummer.
A53: 7 | B53: oktober 2026 | C53: M. van Glabbeek (Bizz4Mation) | D53: 18 initiatieven, 7 bouwstenen en 3 aanbieders toegevoegd uit het rapport Data governance en data delen in het energiedomein (2026); bronlinks aangevuld uit het GitHub-overzicht energie-data/energy-data-governance-project-overview; statussen gecorrigeerd.
A54: 8 | B54: oktober 2026 | C54: M. van Glabbeek (Bizz4Mation) | D54: Bijlage synthese-referentiearchitectuur digitale tweelingen toegevoegd, gebaseerd op DTFL en andere referentiearchitecturen; register met tabblad Referentiearchitectuur.
A55: 9 | B55: 19 oktober 2026 | C55: M. van Glabbeek (Bizz4Mation) | D55: Voorbereiding van de verdiepende gesprekken: samenwerking en deliverables, analysekader ter bespreking, horizontale analyse met 27 werkhypothesen, scopevoorstel, informatiebehoefte per initiatief en interviewinput; afgeleide velden, verificatielijst en tabbladen in het register.
A56: 10 | B56: 19 oktober 2026 | C56: M. van Glabbeek (Bizz4Mation) | D56: Redactie volgens de NEDRA-schrijfwijzer: tekst zelfstandig leesbaar gemaakt, verwijzingen naar eerdere versies en wijzigingsaanleidingen naar deze versiegeschiedenis verplaatst, persoonsnamen vervangen door rollen, derde persoon; versiegeschiedenis en afkortingenlijst toegevoegd; NLDT en ORTESE voluit.
A57: 11 | B57: 21 oktober 2026 | C57: M. van Glabbeek (Bizz4Mation) | D57: Drie bronnen verwerkt: call for proposals KIC NWO-TenneT-Topsector Energie, Datastrategie digital twins voor een toekomstig energiesysteem (RVO, 2026) en projectpagina Impactanalyse Digital Twins. DT-010 en DT-027 toegevoegd; DT-013 en DT-087 geverifieerd en aangevuld; H07 en H23 bijgesteld.
... A60: 14 | B60: 26 oktober 2026 | C60: M. van Glabbeek (Bizz4Mation) | D60: Initiatief DT-146 (HOLON) en bouwsteen Holonic Graph Architecture opgenomen; DT-014 uitgebreid met de netsimulatie van het ESP-lab DT-048 met de aanbesteding en opbouw van het Open Urban Platform en DT-091 met de How-to-digital-twin-methode van DMI; werkhypothese H29 (holarchie); bronnen: Holontool, rapport Holons (2026), A Digital Energy System v0.83 (2026), EPRI (2022) en smart-city-platforms.

Sheet Portfolio
A1: ID | B1: Categoriecode | C1: Categorie | D1: Initiatief | E1: Focus | F1: Gebied | G1: Land | H1: Rol in ecosysteem | I1: Primaire functie | J1: Overige functies | K1: Schaalniveau | L1: Twinniveau | M1: Energiedrager | N1: Volwassenheid | O1: Kaders (aansluiting) | P1: Kadercodes | Q1: Bouwsteencodes | R1: Trekker / partners | S1: NL-betrokkenheid | T1: Status (okt. 2026) | U1: Herbruikbaar / les voor NL (hypothese) | V1: Bron | W1: Breedtegraad | X1: Lengtegraad | Y1: Opgenomen in versie | Z1: Gevalideerd? (ja/nee) | AA1: Scope (RA) | AB1: Twinniveau (genormaliseerd) | AC1: Twinstatus | AD1: Inzetniveau (afgeleid) | AE1: Energiedragers (genormaliseerd) | AF1: NL-rol (genormaliseerd) | AG1: Betrouwbaarheid duiding
A2: DT-001 | B2: K | C2: Kader | D2: Nationaal Plan Energiesysteem (NPE), actualisatie 2026 | E2: Energie | F2: NL | G2: NL | H2: Kader | I2: Scenario & planning | J2: Gezamenlijke besluitvorming | K2: Net / nationaal systeem | L2: n.v.t. | M2: Alle | N2: n.v.t. | O2: NPE | P2: NPE | R2: Ministerie EZK/KGG | S2: Opsteller | T2: Actualisatie gepubliceerd 15-9-2026 | U2: Richtinggevend kader; noemt innovatie randvoorwaarde voor systeemvraagstukken (netcongestie, weerbaarheid) | V2: https://energy-innovation.nl/nl/nieuws/uitdagingen-energiesysteem-vragen-om-gerichte-inzet-van-innovatie/ | W2: 52.08 | X2: 4.31 | Y2: v4 of eerder | Z2: nee | AA2: Ecosysteem | AB2: n.v.t. | AC2: n.v.t. | AD2: - | AE2: Elektriciteit; Gas; Waterstof; Warmte/koude (multi-commodity) | AF2: Trekker/eigenaar | AG2: B primaire bron
A3: DT-002 | B3: K | C3: Kader | D3: Actieagenda Digitalisering Energiesysteem (ADE) | E3: Energie | F3: NL | G3: NL | H3: Kader | I3: Inzicht & monitoring | J3: Scenario & planning, Sturing & optimalisatie, Gezamenlijke besluitvorming | K3: Net / nationaal systeem | L3: n.v.t. | M3: Elektriciteit | N3: n.v.t. | O3: ADE; NPE | P3: ADE;NPE | R3: KGG en TNO (opstellers); programmaregie Energy Innovation NL | S3: Opsteller | T3: Gepubliceerd 11-12-2025; uitvoering sinds Q1 2026 via programma Digitalisering (EUR 250 duizend per jaar); 5 thema's, 12 actielijnen, 29 acties; scope alleen elektriciteit | U3: Actie 1.1.3 digital twin elektriciteitssysteem (KIC, kwartiermaker Faciliteit, decentrale twins); 1.1.4 eisen simulatie-tooling; 1.2.1 energiedata-ecosysteem (o.a. TenneT Digital Spine); 2.2.2 blauwdruk digitale coördinatie; 4.1.2 referentiearchitectuur (alleen data-uitwisseling); 5.1.1 planningsmodellen | V3: https://www.tno.nl/nl/newsroom/2025/12/overheid-tno-topsector-energie-lanceren/ | W3: 52.08 | X3: 4.31 | Y3: v4 of eerder | Z3: nee | AA3: Ecosysteem | AB3: n.v.t. | AC3: n.v.t. | AD3: - | AE3: Elektriciteit | AF3: Trekker/eigenaar | AG3: B primaire bron
A4: DT-003 | B4: K | C4: Kader | D4: NEDRA: Nederlandse Energie Domein Referentie Architectuur | E4: Energie | F4: NL | G4: NL | H4: Kader | I4: Ontwerp & engineering | J4: Gezamenlijke besluitvorming | K4: Net / nationaal systeem | L4: n.v.t. | M4: Alle | N4: 3 Demonstratie/lab | O4: NEDRA; ADE 4.1.2 | P4: NEDRA;ADE;SGAM | Q4: BS-CIM;BS-NBILITY;BS-SAREF;BS-USEF;BS-S2;BS-OPENADR | R4: Energy Innovation NL (Systeemintegratie, Digitalisering); klankbordgroep netbeheerders e.a. | S4: Opsteller | T4: Raamwerk, ArchiMate-model en werkmodel; ORTESE uitgewerkt als praktijkcase (klantreis, waardeketen, bouwblokken, rollen, afspraken) op Digital Energy Systems, 11-12-2025; getoetst in IT-landschap energiehubs (update juni 2026) | U4: Noemt digital twin als componentbouwblok; landingsplaats voor gedeelde taal en bouwblokken | V4: https://energy-innovation.nl/nl/projecten/bouwen-aan-een-robuuste-referentiearchitectuur-voor-de-energiesector/ | W4: 52.09 | X4: 5.12 | Y4: v4 | Z4: nee | AA4: Ecosysteem | AB4: n.v.t. | AC4: n.v.t. | AD4: - | AE4: Elektriciteit; Gas; Waterstof; Warmte/koude (multi-commodity) | AF4: Trekker/eigenaar | AG4: B primaire bron
A5: DT-004 | B5: K | C5: Kader | D5: EU Strategic Roadmap for Digitalisation and AI in Energy | E5: Energie | F5: Europees | G5: EU | H5: Kader | I5: Inzicht & monitoring | J5: Sturing & optimalisatie | K5: Europees | L5: n.v.t. | M5: Alle | N5: n.v.t. | O5: EU | P5: EU-RM26 | R5: Europese Commissie | S5: Via EZK/KGG en netbeheerders | T5: Gepresenteerd 3-6-2026 (Tech Sovereignty Package); actie 3: digital twin toolbox-blauwdruk ENTSO-E/DSO Entity medio 2026 | U5: Europese referentie voor NL-twins; best practices 2027 | V5: https://energy.ec.europa.eu/news/commission-presents-measures-digitalise-europes-energy-system-while-ensuring-sustainable-2026-06-03_en | W5: 50.85 | X5: 4.35 | Y5: v4 of eerder | Z5: nee | AA5: Ecosysteem | AB5: n.v.t. | AC5: n.v.t. | AD5: - | AE5: Elektriciteit; Gas; Waterstof; Warmte/koude (multi-commodity) | AF5: Partner/deelnemer | AG5: B primaire bron
A6: DT-005 | B6: K | C6: Kader | D6: EU Actieplan Digitalisering Energiesysteem (2022) | E6: Energie | F6: Europees | G6: EU | H6: Kader | I6: Inzicht & monitoring | J6: Sturing & optimalisatie | K6: Europees | L6: n.v.t. | M6: Elektriciteit | N6: n.v.t. | O6: EU | P6: EU-AP22 | R6: Europese Commissie | S6: Via EZK/KGG | T6: Sinds okt. 2022; basis voor ENTSO-E/DSO Entity grid twin | U6: Grondslag ADE en TwinEU | V6: https://energy.ec.europa.eu/news/commission-welcomes-cooperation-between-entso-e-and-eu-dso-entity-digital-electricity-grid-twin-2022-12-20_en | W6: 50.85 | X6: 4.35 | Y6: v4 of eerder | Z6: nee | AA6: Ecosysteem | AB6: n.v.t. | AC6: n.v.t. | AD6: - | AE6: Elektriciteit | AF6: Partner/deelnemer | AG6: B primaire bron
A7: DT-006 | B7: K | C7: Kader | D7: Programma Digitale Tweeling / NLDT-architectuur | E7: GO | F7: NL | G7: NL | H7: Kader | I7: Gezamenlijke besluitvorming | J7: Scenario & planning | K7: Gemeente / regio | L7: n.v.t. | M7: GO (incl. energie als thema) | N7: 3 Demonstratie/lab | O7: NLDT/FDS | P7: NLDT | Q7: BS-CITYGML;BS-3DTILES | R7: VRO, Geonovum, VNG, Kadaster | S7: Opsteller | T7: Lopend; testbeds 2024-2026 | U7: Federatief stelselpatroon (data-rekenmodel-visualisatie ontkoppeld) herbruikbaar voor energie | V7: https://geonovum.github.io/NLDT-Architectuur/ | W7: 52.16 | X7: 5.39 | Y7: v4 of eerder | Z7: nee | AA7: Ecosysteem | AB7: n.v.t. | AC7: n.v.t. | AD7: - | AE7: n.v.t. | AF7: Trekker/eigenaar | AG7: B primaire bron
A8: DT-007 | B8: K | C8: Kader | D8: SGAM: Smart Grid Architecture Model | E8: Energie | F8: Europees | G8: EU | H8: Kader | I8: Ontwerp & engineering | J8: Gezamenlijke besluitvorming | K8: Europees | L8: n.v.t. | M8: Elektriciteit | N8: n.v.t. | O8: SGAM; NEDRA | P8: SGAM;NEDRA | R8: CEN-CENELEC-ETSI Smart Grid Coordination Group (mandaat M/490) | S8: Gebruikt in NEDRA-modelbouwblokken; NL-architecten (o.a. netbeheerders) werken ermee | T8: Referentiemodel sinds 2012; basis voor positionering in Horizon-projecten (o.a. GRID-PRO werkt 'SGAM-conform') | U8: Gedeelde taal om twin-componenten te plaatsen in domeinen, zones en interoperabiliteitslagen; ankerpunt tussen NEDRA en EU-projecten | V8: https://referentiearchitectuurtopsectorenergie.github.io/NEDRA/detail/afstemming/modellen/index.html | W8: 50.85 | X8: 4.35 | Y8: v5 | Z8: nee | AA8: Ecosysteem | AB8: n.v.t. | AC8: n.v.t. | AD8: - | AE8: Elektriciteit | AF8: Gebruiker | AG8: B primaire bron
A9: DT-008 | B9: K | C9: Kader | D9: DSGO: Digitaal Stelsel Gebouwde Omgeving | E9: Energie + GO | F9: NL | G9: NL | H9: Kader | I9: Gezamenlijke besluitvorming | J9: Inzicht & monitoring | K9: Gebouw / site | L9: n.v.t. | M9: GO (gebouwen, installaties) | N9: 4 Operationeel | O9: DSGO; NLDT | P9: DSGO;NLDT | Q9: BS-ISHARE | R9: digiGO, bouw- en installatiesector | S9: Trekker | T9: Operationeel afsprakenstelsel; inventariseerde in 2022 de federatieve componenten voor digitale tweelingen (DSGO/Geonovum) | U9: Trust- en afsprakenlaag voor gebouw- en installatiedata richting energie-twins (o.a. DVU); brug GO-energie op gebouwniveau | V9: https://www.digigo.nu/afsprakenstelsel/ | W9: 52.13 | X9: 5.29 | Y9: v5 | Z9: nee | AA9: Ecosysteem | AB9: n.v.t. | AC9: n.v.t. | AD9: - | AE9: n.v.t. | AF9: Trekker/eigenaar | AG9: B primaire bron
A10: DT-009 | B10: K | C10: Kader | D10: EU Local Digital Twins: LDT CitiVERSE EDIC, LDT-toolbox en MIMs Plus | E10: GO | F10: Europees | G10: EU | H10: Kader | I10: Gezamenlijke besluitvorming | J10: Scenario & planning | K10: Europees | L10: n.v.t. | M10: GO (energie als thema) | N10: 3 Demonstratie/lab | O10: LDT | P10: EU-LDT | Q10: BS-NGSILD | R10: Europese Commissie; EDIC met 15 lidstaten (incl. NL), zetel Valencia; OASC (toolbox, MIMs Plus) | S10: NL is lid via nLDT-programma en Geonovum | T10: EDIC actief; toolbox en conformiteitstesten afgerond sept. 2025 | U10: Europese aansluitvoorwaarden voor lokale twins; energie is er nog geen eigen laag. Kansrijk koppelpunt voor gemeentelijke energietwins | V10: https://ldtcitiverse-edic.eu/ | W10: 39.47 | X10: -0.38 | Y10: v5 | Z10: nee | AA10: Ecosysteem | AB10: n.v.t. | AC10: n.v.t. | AD10: - | AE10: n.v.t. | AF10: Partner/deelnemer | AG10: B primaire bron
A11: DT-010 | B11: K | C11: Kader | D11: Datastrategie digital twins voor een toekomstig energiesysteem (RVO/Topsector Energie, 2026) | E11: Energie | F11: NL | G11: NL | H11: Kader | I11: Gezamenlijke besluitvorming | J11: Scenario & planning | K11: Gemeente / regio | L11: n.v.t. | M11: Multi-commodity | N11: 3 Demonstratie/lab | R11: RVO/Topsector Energie (opdrachtgever); Witteveen+Bos, Gradyent, TNO, Quintel, CE Delft, ENTRANCE (Hanze) | S11: Opdrachtgever | T11: Definitief april 2026 (publiek document); inhoud niet samengevat vanwege auteursrechtvoorbehoud (geen tekst- en datamining of verwerking met AI) | U11: Volgens de projectpagina van Witteveen+Bos bedoeld als blauwdruk voor andere gemeenten: welke data een twin nodig heeft, welke kwaliteit en hoe levering contractueel wordt geregeld | V11: https://www.witteveenbos.com/projects/emmen-and-ortese ; Datastrategie_Digital_Twins_voor_een_toekomstig_energiesysteem.pdf (W+B, ref. 140813/26-006.618) | W11: 52.09 | X11: 5.12 | Y11: v11 | Z11: nee | AA11: Ecosysteem | AB11: n.v.t. | AC11: n.v.t. | AD11: - | AE11: Multi-commodity (dragers niet gespecificeerd) | AF11: Trekker/eigenaar | AG11: B primaire bron
A12: DT-011 | B12: K | C12: Kader | D12: DSSC Blueprint: bouwblokken voor data spaces (Data Spaces Support Centre) | E12: Overig | F12: Europees | G12: EU | H12: Kader | I12: Gezamenlijke besluitvorming | J12: Ontwerp & engineering | K12: Europees | L12: n.v.t. | M12: n.v.t. | N12: 3 Demonstratie/lab | O12: DSSC | P12: DSSC | Q12: BS-DSP;BS-DCP;BS-EDC;BS-DCAT | R12: Data Spaces Support Centre (Europese Commissie); TNO namens NL lid | S12: TNO | T12: Blueprint met technische en organisatorische bouwblokken; basis voor EU-standaardisatie onder de Data Act | U12: Kapstok voor de federatieband van de referentiearchitectuur; gebruikt in de CDO-inventarisatie (DT-096) | V12: https://dssc.eu/ ; Eindrapport Inventarisatie Architectuur Data Ecosystemen tbv CDO IenW (Geonovum, 2025) | W12: 50.85 | X12: 4.35 | Y12: v12 | Z12: nee | AA12: Ecosysteem | AB12: n.v.t. | AC12: n.v.t. | AD12: - | AE12: n.v.t. | AF12: Partner/deelnemer | AG12: B primaire bron
A13: DT-012 | B13: R | C13: Faciliteit of R&D (NL) | D13: Nationale Faciliteit Digital Twin Elektriciteitssysteem | E13: Energie | F13: NL | G13: NL | H13: Faciliteit/R&D | I13: Scenario & planning | J13: Onderzoek & training, Inzicht & monitoring | K13: Net / nationaal systeem | L13: Tweeling (beoogd) | M13: Elektriciteit | N13: 1 Verkenning | O13: ADE 1.1.3; NPE | P13: ADE;NPE | R13: Ministerie KGG, TU Delft, TenneT, Energy Innovation NL | S13: Trekker | T13: Aangekondigd 29-6-2026; zes deelsystemen in één model | U13: Potentiële nationale referentietwin; ADE-actie 1.1.3 lijkt hier te landen (te verifiëren) | V13: https://www.engineersonline.nl/digital-twin-moet-risicos-in-het-elektriciteitssysteem-eerder-blootleggen/ | W13: 52 | X13: 4.37 | Y13: v4 of eerder | Z13: nee | AA13: Twin-instantie | AB13: Tweeling | AC13: Beoogd | AD13: 5 Sturende tweeling (beoogd) | AE13: Elektriciteit | AF13: Trekker/eigenaar | AG13: C secundaire bron
A14: DT-013 | B14: R | C14: Faciliteit of R&D (NL) | D14: KIC 'Unlocking Digital Twin Capabilities for Electricity Utilities' | E14: Energie | F14: NL | G14: NL | H14: Faciliteit/R&D | I14: Onderzoek & training | K14: Net / nationaal systeem | L14: Tweeling (prototype) | M14: Elektriciteit | N14: 1 Verkenning | O14: KIC/MMIP; ADE | P14: ADE;TSE-INNOV | R14: NWO, TenneT, Topsector Energie (Energy Innovation NL) | S14: Trekker | T14: Call-tekst: max. EUR 5,76 mln NWO-subsidie (max. 95%, min. 5% cofinanciering), één consortium, max. 6 jaar; vooraanmelding 10-2-2026, volledige aanvraag 8-9-2026, besluit NWO-bestuur januari 2027 (TenneT-pagina noemt EUR 6,2 mln en 25-8-2026; te verifiëren) | U14: Bouwstenen (methoden, algoritmen, architecturen) in zes domeinen: assets, net (EMT/RMS), netgebruikers, kritieke OT, energiemarkten, digitale backbone; resultaten bedoeld voor de Nationale Faciliteit (DT-012); federatieprincipes | V14: Call-for-Proposals-NWO-TenneT-TSE-NL_0.pdf ; https://www.nwo.nl/en/researchprogrammes/knowledge-and-innovation-covenant/kic-2024-2027/demand-2024-2027/unlocking-digital-twin-capabilities-for-electricity-utilities | W14: 52.08 | X14: 4.31 | Y14: v4 of eerder | Z14: nee | AA14: Twin-instantie | AB14: Tweeling | AC14: Beoogd | AD14: 5 Sturende tweeling (beoogd) | AE14: Elektriciteit | AF14: Trekker/eigenaar | AG14: B primaire bron
A15: DT-014 | B15: R | C15: Faciliteit of R&D (NL) | D15: Control Room of the Future en Digital Twin elektriciteitsnetwerk (ESP-lab TU Delft) | E15: Energie | F15: NL | G15: NL | H15: Faciliteit/R&D | I15: Sturing & optimalisatie | J15: Onderzoek & training | K15: Net / nationaal systeem | L15: Tweeling | M15: Elektriciteit | N15: 3 Demonstratie/lab | O15: ADE 4.3 | P15: ADE;HORIZON | R15: TU Delft met TenneT, Alliander, Stedin, Siemens, GE | S15: Trekker | T15: Operationeel lab | U15: Testomgeving voor operatie, AI en cyberweerbaarheid; het lab simuleert het hele Nederlandse net (met TenneT) om ingrepen als nieuwe windparken, elektrisch laden en cyberaanvallen te testen; verhouding tot DT-012 en DT-027 te verifiëren | V15: https://www.tudelft.nl/en/eemcs/research/facilities/esp-lab/infrastructure/digital-twin ; https://www.tudelft.nl/ewi/onderzoek/faciliteiten/esp-lab/infrastructuur/digital-twin-elektriciteitsnetwerk | W15: 52 | X15: 4.37 | Y15: v4 of eerder | Z15: nee | AA15: Twin-instantie | AB15: Tweeling | AC15: Gerealiseerd | AD15: 5 Sturende tweeling | AE15: Elektriciteit | AF15: Trekker/eigenaar | AG15: B primaire bron
A16: DT-015 | B16: R | C16: Faciliteit of R&D (NL) | D16: TU Delft / TenneT simulatie Nederlands transportnet | E16: Energie | F16: NL | G16: NL | H16: Faciliteit/R&D | I16: Scenario & planning | J16: Onderzoek & training | K16: Net / nationaal systeem | L16: Schaduw | M16: Elektriciteit | N16: 3 Demonstratie/lab | O16: ADE 1.1.3 | P16: ADE | Q16: BS-CIM | R16: TU Delft, TenneT | S16: Trekker | T16: Onderzoek; ca. kwart transportnet, uitbreiding gepland | U16: Voorloper nationale faciliteit | V16: https://www.entsoe.eu/technopedia/techsheets/digital-twin-dt/ | W16: 52 | X16: 4.37 | Y16: v4 of eerder | Z16: nee | AA16: Twin-instantie | AB16: Schaduw | AC16: Gerealiseerd | AD16: 4 Scenario-tweeling | AE16: Elektriciteit | AF16: Trekker/eigenaar | AG16: B primaire bron
A17: DT-016 | B17: R | C17: Faciliteit of R&D (NL) | D17: SynergyS: Smart Multi-Commodity Energy System | E17: Energie | F17: NL | G17: NL | H17: Faciliteit/R&D | I17: Sturing & optimalisatie | J17: Onderzoek & training | K17: Wijk / bedrijventerrein / hub | L17: Tweeling (lab) | M17: Elektriciteit, H2, warmte | N17: 3 Demonstratie/lab | O17: Systeemintegratie (MOOI/TSE) | P17: TSE-INNOV | R17: Hanze, TU Delft, RUG, TNO, Groningen Seaports, Energiecampus Leeuwarden e.a. | S17: Trekker | T17: Afgerond (kennisbank 9-12-2025) | U17: Multi-commodity sturing via lokale markt en digital twins; relevant voor energiehubs | V17: https://energy-innovation.nl/nl/kennisbank/synergys/ | W17: 53.22 | X17: 6.57 | Y17: v4 of eerder | Z17: nee | AA17: Twin-instantie | AB17: Tweeling | AC17: Lab | AD17: 5 Sturende tweeling (lab) | AE17: Elektriciteit; Waterstof; Warmte/koude (multi-commodity) | AF17: Trekker/eigenaar | AG17: B primaire bron
A18: DT-017 | B18: R | C18: Faciliteit of R&D (NL) | D18: Digital Twin as a Service-testbeds (Geonovum) | E18: GO | F18: NL | G18: NL | H18: Faciliteit/R&D | I18: Onderzoek & training | J18: Ontwerp & engineering | K18: Gemeente / regio | L18: n.v.t. | M18: n.v.t. | N18: 3 Demonstratie/lab | O18: NLDT | P18: NLDT | R18: Geonovum; Almere, Dronten, Rotterdam, Dordrecht, Zwolle | S18: Trekker | T18: Testbed 1 (2024), Testbed 2 (2025) en Testbed 2026 'Processes and Recipes' lopend | U18: Testbedformat met koppelvlakken en 'recepten' is ook bruikbaar om een energie-use case op NLDT-architectuur te beproeven | V18: https://dmi-ecosysteem.nl/blog/communitydag-met-digital-twins-gaat-het-leven/ | W18: 52.16 | X18: 5.39 | Y18: v6 | Z18: nee | AA18: Twin-instantie | AB18: n.v.t. | AC18: n.v.t. | AD18: - | AE18: n.v.t. | AF18: Trekker/eigenaar | AG18: B primaire bron
A19: DT-018 | B19: R | C19: Faciliteit of R&D (NL) | D19: Fieldlabs nDTFL (Flevoland/Almere, Utrecht/Amersfoort, RWS, Nijmegen, Zuid-Holland, Breda/Den Bosch) | E19: GO | F19: NL | G19: NL | H19: Faciliteit/R&D | I19: Gezamenlijke besluitvorming | J19: Scenario & planning | K19: Gemeente / regio | L19: Model | M19: n.v.t. | N19: 3 Demonstratie/lab | O19: NLDT | P19: NLDT | R19: Geonovum i.o.v. BZK, RWS en provincie Zuid-Holland | S19: Trekker | T19: Historisch (2021-2022); opgevolgd door nLDT-programma en testbeds | U19: 'DT Energie' stond al als dataspace in het nDTFL-voorstel; de koppeling is daarna niet uitgewerkt | V19: Presentatie nDTFL (Geonovum) en Investeringsvoorstel DTFL (2021) | W19: 52.16 | X19: 5.39 | Y19: v6 | Z19: nee | AA19: Twin-instantie | AB19: Model | AC19: Gerealiseerd | AD19: 1 Digitaal model | AE19: n.v.t. | AF19: Trekker/eigenaar | AG19: C secundaire bron
A20: DT-019 | B20: R | C20: Faciliteit of R&D (NL) | D20: Rijkswaterstaat: regie op digital twins | E20: Overig | F20: NL | G20: NL | H20: Faciliteit/R&D | I20: Inzicht & monitoring | J20: Voorspellen | K20: Net / nationaal systeem | L20: Model/schaduw | M20: n.v.t. | N20: 3 Demonstratie/lab | O20: - | P20: - | R20: Rijkswaterstaat; ca. 40 experimenten, o.a. IJsselbrug en Maeslantkering | S20: Trekker | T20: Sinds 2022 | U20: Voorbeeld van centrale regie op veel twin-experimenten binnen één organisatie | V20: https://dutchitchannel.nl/706207/rijkswaterstaat-neemt-regie-bij-digital-twins.html | W20: 52.09 | X20: 5.12 | Y20: v6 | Z20: nee | AA20: Twin-instantie | AB20: Model of schaduw (onzeker) | AC20: Gerealiseerd | AD20: 3 Voorspellende schaduw | AE20: n.v.t. | AF20: Trekker/eigenaar | AG20: C secundaire bron
A21: DT-020 | B21: R | C21: Faciliteit of R&D (NL) | D21: Digital Twin Geohub (Universiteit Twente / ITC) | E21: GO | F21: NL | G21: NL | H21: Faciliteit/R&D | I21: Onderzoek & training | J21: Scenario & planning | K21: Gemeente / regio | L21: n.v.t. | M21: n.v.t. | N21: 3 Demonstratie/lab | O21: - | P21: - | R21: Universiteit Twente; o.a. planningsondersteuning Enschede | S21: Trekker | T21: Onderzoek | U21: Kennispartner voor TwinTwente en regionale GO-twins | V21: https://www.utwente.nl/en/digital-society/research/digitalisation/digital-twin-geohub/projects/ | W21: 52.24 | X21: 6.85 | Y21: v6 | Z21: nee | AA21: Twin-instantie | AB21: n.v.t. | AC21: n.v.t. | AD21: - | AE21: n.v.t. | AF21: Trekker/eigenaar | AG21: B primaire bron
A22: DT-021 | B22: R | C22: Faciliteit of R&D (NL) | D22: Centre for BOLD Cities: Urban Digital Twins | E22: GO | F22: NL | G22: NL | H22: Faciliteit/R&D | I22: Onderzoek & training | J22: Gezamenlijke besluitvorming | K22: Gemeente / regio | L22: n.v.t. | M22: n.v.t. | N22: 3 Demonstratie/lab | O22: - | P22: - | R22: Universiteit Leiden, Erasmus Universiteit, TU Delft | S22: Trekker | T22: Onderzoek | U22: Sociale en bestuurlijke kant van stedelijke twins; relevant voor gezamenlijke besluitvorming | V22: https://www.centre-for-bold-cities.nl/projects/urban-digital-twins | W22: 51.92 | X22: 4.48 | Y22: v6 | Z22: nee | AA22: Twin-instantie | AB22: n.v.t. | AC22: n.v.t. | AD22: - | AE22: n.v.t. | AF22: Trekker/eigenaar | AG22: B primaire bron
A23: DT-022 | B23: R | C23: Faciliteit of R&D (NL) | D23: DEMOSES: simulaties van toekomstige energiesystemen | E23: Energie | F23: NL | G23: NL | H23: Faciliteit/R&D | I23: Scenario & planning | J23: Onderzoek & training | K23: Net / nationaal systeem | L23: Model | M23: Multi-commodity | N23: 3 Demonstratie/lab | O23: - | P23: - | R23: TU Delft, TNO, TU/e, Eneco, AgroEnergy, Tata Steel, TenneT, Stedin, Alliander, Gasunie; Netherlands eScience Center | S23: Trekker | T23: Lopend onderzoek; computersimulaties van combinaties van flexibiliteit, opslag en opwek | U23: Rekenmodellen op systeemniveau; kandidaat-bouwsteen voor de Nationale Faciliteit (noemt zich geen twin) | V23: Rapport datagovernance 2026, use case P026: https://www.esciencecenter.nl/projects/designing-and-modelling-future-systems-of-energy-systems-demoses/ | W23: 52 | X23: 4.37 | Y23: v7 | Z23: nee | AA23: Twin-instantie | AB23: Model | AC23: Gerealiseerd | AD23: 1 Digitaal model | AE23: Multi-commodity (dragers niet gespecificeerd) | AF23: Trekker/eigenaar | AG23: C secundaire bron
A24: DT-023 | B24: R | C24: Faciliteit of R&D (NL) | D24: TeSopS: integraal techno-economisch-sociaal energiesysteemmodel | E24: Energie | F24: NL | G24: NL | H24: Faciliteit/R&D | I24: Scenario & planning | J24: Gezamenlijke besluitvorming | K24: Gemeente / regio | L24: Model | M24: Multi-commodity | N24: 3 Demonstratie/lab | O24: - | P24: - | R24: Rijksuniversiteit Groningen, TNO, gemeente Groningen/WarmteStad, Enexis, ING, PowerChainger, De Groene Afslag; NWO | S24: Trekker | T24: Afgerond (NWO-onderzoek, gestart 2021) | U24: Voegt sociale en economische lagen toe aan het systeemmodel; relevant voor gezamenlijke besluitvorming in regionale twins | V24: Rapport datagovernance 2026, use case P025: https://www.rug.nl/news/2021/07/0701-nwo-esi-far-subsidie?lang=en | W24: 53.22 | X24: 6.57 | Y24: v7 | Z24: nee | AA24: Twin-instantie | AB24: Model | AC24: Gerealiseerd | AD24: 1 Digitaal model | AE24: Multi-commodity (dragers niet gespecificeerd) | AF24: Trekker/eigenaar | AG24: C secundaire bron
A25: DT-024 | B25: R | C25: Faciliteit of R&D (NL) | D25: Realtime systeemwerking voor netwerkverbetering en transportefficiëntie (MOOI) | E25: Energie | F25: NL | G25: NL | H25: Faciliteit/R&D | I25: Sturing & optimalisatie | J25: Inzicht & monitoring | K25: Net / nationaal systeem | L25: Tweeling (lab) | M25: Elektriciteit | N25: 2 Pilot/PoC | O25: MOOI; ADE | P25: TSE-INNOV;ADE | R25: Alliander, Enexis, Stedin, TenneT, TU Eindhoven | S25: Trekker | T25: Afgerond (MOOI); stuuralgoritmes en systeemarchitecturen voor real-time operatie op LS en HS | U25: Alle netbeheerders samen aan real-time systeemoperatie: de operationele kant van een grid-twin, verwant aan Control Room of the Future | V25: Rapport datagovernance 2026, use case P016: https://www.duurzaam-ondernemen.nl/65-miljoen-euro-voor-circulaire-energie-innovatie-in-de-gebouwde-omgeving/ | W25: 51.45 | X25: 5.48 | Y25: v7 | Z25: nee | AA25: Twin-instantie | AB25: Tweeling | AC25: Lab | AD25: 5 Sturende tweeling (lab) | AE25: Elektriciteit | AF25: Trekker/eigenaar | AG25: C secundaire bron
A26: DT-025 | B26: R | C26: Faciliteit of R&D (NL) | D26: ORKEST: actief capaciteitsbeheer en asset intelligence (MOOI) | E26: Energie | F26: NL | G26: NL | H26: Faciliteit/R&D | I26: Inzicht & monitoring | J26: Sturing & optimalisatie | K26: Net / nationaal systeem | L26: Model | M26: Elektriciteit | N26: 2 Pilot/PoC | O26: MOOI | P26: TSE-INNOV | R26: Stedin, TU Eindhoven, Technolution, DNV, Netbeheer Nederland, Phase to Phase | S26: Trekker | T26: Lopend (MOOI); netdata en componentbelasting voor capaciteitsbeheer en betrouwbaarheidsanalyse | U26: Asset- en netmodellen bij Stedin; aanvulling op Stedin-netmodellen (DT-037) | V26: Rapport datagovernance 2026, use case P002: https://projecten.topsectorenergie.nl/projecten/orkest-optimal-integration-of-network-flexibiilty-and-asset-intelligence-to-increase-large-scale-integration-of-res-while-maintaining-reliability-37711 | W26: 51.92 | X26: 4.48 | Y26: v7 | Z26: nee | AA26: Twin-instantie | AB26: Model | AC26: Gerealiseerd | AD26: 1 Digitaal model | AE26: Elektriciteit | AF26: Trekker/eigenaar | AG26: C secundaire bron
A27: DT-026 | B27: R | C27: Faciliteit of R&D (NL) | D27: The Green Village: DC smart grid lab (TU Delft) | E27: Energie | F27: NL | G27: NL | H27: Faciliteit/R&D | I27: Onderzoek & training | J27: Ontwerp & engineering | K27: Wijk / bedrijventerrein / hub | L27: n.v.t. | M27: Elektriciteit (DC), H2, warmte | N27: 4 Operationeel | O27: - | P27: - | R27: TU Delft, The Green Village en projectpartners | S27: Trekker | T27: Operationele regelluwe proeftuin met waterstof-, gelijkspannings- en lagetemperatuurwarmtenetten | U27: Fysieke proeftuin om twins te valideren; schaalmodel ook gebruikt door SynergyS | V27: Rapport datagovernance 2026, use case P010: https://www.thegreenvillage.org/toekomstig-energiesysteem/ | W27: 52 | X27: 4.37 | Y27: v7 | Z27: nee | AA27: Twin-instantie | AB27: n.v.t. | AC27: n.v.t. | AD27: - | AE27: Elektriciteit; Waterstof; Warmte/koude (multi-commodity) | AF27: Trekker/eigenaar | AG27: C secundaire bron
A28: DT-027 | B28: R | C28: Faciliteit of R&D (NL) | D28: UTOPYS: academische real-time EMT-simulator voor nationale elektriciteitssystemen (NWO LSRI) | E28: Energie | F28: NL | G28: NL | H28: Faciliteit/R&D | I28: Onderzoek & training | J28: Scenario & planning, Voorspellen | K28: Net / nationaal systeem | L28: Tweeling (lab) | M28: Elektriciteit | N28: 1 Verkenning | O28: - | P28: - | R28: TU Delft (trekker), TU/e, UT, RUG, UU, EUR, Radboud Universiteit, CWI; SURF | S28: Trekker | T28: NWO LSRI toegekend (EUR 16,5 mln, ca. tien jaar); bekendgemaakt nov. 2025; in opbouw | U28: Open modellen en data; real-time EMT op nationale schaal; kandidaat-kennisbron of deelsysteem voor de Nationale Faciliteit (relatie niet vastgesteld) | V28: https://www.cwi.nl/en/news/major-nwo-grant-to-build-worlds-largest-digital-twin-for-energy-system-studies/ ; https://ecda.eur.nl/2026/03/12/e16-5m-nwo-grant-to-research-digital-twins-for-energy-systems/ | W28: 52 | X28: 4.37 | Y28: v11 | Z28: nee | AA28: Twin-instantie | AB28: Tweeling | AC28: Lab | AD28: 5 Sturende tweeling (lab) | AE28: Elektriciteit | AF28: Trekker/eigenaar | AG28: B primaire bron
A29: DT-028 | B29: T | C29: Twin-instantie (NL) | D29: ORTESE Emmen: digital twin/shadow lokaal energiesysteem (incl. PRIME) | E29: Energie | F29: NL | G29: NL | H29: Twin-instantie | I29: Scenario & planning | J29: Gezamenlijke besluitvorming | K29: Gemeente / regio | L29: Schaduw | M29: Multi-commodity | N29: 2 Pilot/PoC | O29: NEDRA; NPE; Systeemintegratie | P29: NEDRA;NPE;TSE-INNOV | Q29: BS-ETM;BS-ESDL | R29: Gem. Emmen, prov. Drenthe, Enexis, KGG; W+B, Gradyent, TNO, Quintel, CE Delft, ENTRANCE | S29: Trekker | T29: Lopend; datastrategie (DT-010) opgeleverd in 2026; uitgewerkt als praktijkcase van NEDRA (DT-003) | U29: Expliciet bedoeld als blauwdruk voor andere gemeenten; ambitie van meerdere multi-commodity energiehubs; uitgewerkt met het NEDRA-denkkader (klantreis, waardeketen in vijf stappen, bouwblokken, rollen) | V29: https://energy-innovation.nl/nl/kennisbank/datastrategie-maakt-datapuzzel-achter-digital-twin-voor-ortese-concreet/ ; https://www.witteveenbos.com/projects/emmen-and-ortese | W29: 52.78 | X29: 6.9 | Y29: v4 of eerder | Z29: nee | AA29: Twin-instantie | AB29: Schaduw | AC29: Gerealiseerd | AD29: 4 Scenario-tweeling | AE29: Multi-commodity (dragers niet gespecificeerd) | AF29: Trekker/eigenaar | AG29: B primaire bron
A30: DT-029 | B30: T | C30: Twin-instantie (NL) | D30: Port of Rotterdam: Virtual Energy System (VES) | E30: Energie | F30: NL | G30: NL | H30: Twin-instantie | I30: Scenario & planning | J30: Gezamenlijke besluitvorming | K30: Wijk / bedrijventerrein / hub | L30: Schaduw | M30: Elektriciteit, stoom, H2, warmte | N30: 2 Pilot/PoC | O30: NPE (industrieclusters) | P30: NPE | R30: Havenbedrijf Rotterdam, Gradyent | S30: Trekker | T30: Proof of value Maasvlakte afgerond; besluit vervolg 2026 | U30: Clustertwin; herbruikbaar voor andere industrieclusters | V30: https://publications.portofrotterdam.com/digital-report-2025/case-study-4 | W30: 51.95 | X30: 4.03 | Y30: v4 of eerder | Z30: nee | AA30: Twin-instantie | AB30: Schaduw | AC30: Gerealiseerd | AD30: 4 Scenario-tweeling | AE30: Elektriciteit; Waterstof; Warmte/koude (multi-commodity) | AF30: Trekker/eigenaar | AG30: B primaire bron
A31: DT-030 | B31: T | C31: Twin-instantie (NL) | D31: DigiPACT: haven-twin voor emissiereductie | E31: Energie | F31: NL | G31: NL | H31: Twin-instantie | I31: Scenario & planning | J31: Onderzoek & training | K31: Wijk / bedrijventerrein / hub | L31: Schaduw | M31: Emissies, energie | N31: 2 Pilot/PoC | O31: - | P31: - | R31: Havenbedrijf Rotterdam; TU Delft, EUR, Erasmus MC (Convergence) | S31: Trekker | T31: Lopend | U31: Onderzoeksbasis haven | V31: https://convergence.nl/reducing-emissions-in-the-port-of-rotterdam-with-a-digital-twin/ | W31: 51.92 | X31: 4.48 | Y31: v4 of eerder | Z31: nee | AA31: Twin-instantie | AB31: Schaduw | AC31: Gerealiseerd | AD31: 4 Scenario-tweeling | AE31: n.v.t. | AF31: Trekker/eigenaar | AG31: C secundaire bron
A32: DT-031 | B32: T | C32: Twin-instantie (NL) | D32: Digital Twin Drechtsteden (HOLON/ZEnMo) | E32: Energie | F32: NL | G32: NL | H32: Twin-instantie | I32: Scenario & planning | J32: Gezamenlijke besluitvorming | K32: Wijk / bedrijventerrein / hub | L32: Model/schaduw | M32: Elektriciteit, warmte | N32: 4 Operationeel | O32: ADE 2.2; energiehubs; DMI | P32: ADE;TSE-INNOV;NLDT | Q32: BS-HOLON | R32: RES-regio Drechtsteden, Programmabureau Energieakkoord Drechtsteden, Werkgevers Drechtsteden, gemeenten, ondernemersverenigingen, energiecoöperaties, Zenmo | S32: Trekker | T32: Toegepast op Antoniapolder en Groote Lindt; in doorontwikkeling naar schaalniveau Drechtsteden; scenario's voor warmtetransitie, netbelasting en energiehubs (rapport datagovernance 2026, P062) | U32: Herhaalbare aanpak bedrijventerreinen; opschaling via DMI | V32: https://www.drechtstedenenergie.nl/digitaltwindrechtsteden ; https://www.smartdeltadrechtsteden.nl/nieuws/simulatietool-helpt-slim-om-te-gaan-met-stroom-bij-warmtetransitie?sresult=1265987673&swords=digital+twin ; https://www.smartdeltadrechtsteden.nl/nieuws/simulatietool-digital-twin-helpt-ondernemers-drechtsteden-bij-aanpak-netcongestie | W32: 51.81 | X32: 4.67 | Y32: v4 of eerder | Z32: nee | AA32: Twin-instantie | AB32: Model of schaduw (onzeker) | AC32: Gerealiseerd | AD32: 4 Scenario-tweeling | AE32: Elektriciteit; Warmte/koude (multi-commodity) | AF32: Trekker/eigenaar | AG32: B primaire bron
A33: DT-032 | B33: T | C33: Twin-instantie (NL) | D33: Amersfoort De Wieken-Vinkenhoef energiehub-twin | E33: Energie | F33: NL | G33: NL | H33: Twin-instantie | I33: Scenario & planning | J33: Gezamenlijke besluitvorming | K33: Wijk / bedrijventerrein / hub | L33: Model | M33: Elektriciteit | N33: 2 Pilot/PoC | O33: Energiehubs | P33: TSE-INNOV | Q33: BS-HOLON | R33: Gem. Amersfoort, ZEnMo e.a. | S33: Trekker | T33: Sinds 2023 | U33: Zelfde modelbasis als Drechtsteden | V33: https://stadszaken.nl/artikel/8883/een-digital-twin-van-het-energienet-in-delft-is-het-gelukt | W33: 52.16 | X33: 5.39 | Y33: v4 of eerder | Z33: nee | AA33: Twin-instantie | AB33: Model | AC33: Gerealiseerd | AD33: 1 Digitaal model | AE33: Elektriciteit | AF33: Trekker/eigenaar | AG33: C secundaire bron
A34: DT-033 | B34: T | C34: Twin-instantie (NL) | D34: Energy Hub Optimizer: ECAH Amsterdamse haven | E34: Energie | F34: NL | G34: NL | H34: Twin-instantie | I34: Scenario & planning | J34: Gezamenlijke besluitvorming | K34: Wijk / bedrijventerrein / hub | L34: Model | M34: Elektriciteit, warmte | N34: 2 Pilot/PoC | O34: Energiehubs; TKI E&I | P34: TSE-INNOV | R34: Quo Mare i.o.v. RVO en TKI Energie en Industrie; 12 ECAH-bedrijven | S34: Trekker | T34: Getest (juli 2025) | U34: Scenario-optimalisatie voor collectieven | V34: https://energy-innovation.nl/nl/nieuws/energy-hub-optimizer-biedt-bedrijven-scenarios-voor-lagere-energiekosten-verduurzaming-en-autonomie/ | W34: 52.41 | X34: 4.83 | Y34: v4 of eerder | Z34: nee | AA34: Twin-instantie | AB34: Model | AC34: Gerealiseerd | AD34: 1 Digitaal model | AE34: Elektriciteit; Warmte/koude (multi-commodity) | AF34: Trekker/eigenaar | AG34: B primaire bron
A35: DT-034 | B35: T | C35: Twin-instantie (NL) | D35: TU Delft campusnet-twin (Argaleo) | E35: Energie | F35: NL | G35: NL | H35: Twin-instantie | I35: Inzicht & monitoring | J35: Scenario & planning | K35: Wijk / bedrijventerrein / hub | L35: Schaduw/tweeling | M35: Elektriciteit | N35: 3 Demonstratie/lab | O35: ADE 1.1.2 | P35: ADE | R35: TU Delft, Argaleo; Stedin betrokken | S35: Trekker | T35: Operationeel sinds maart 2026; ca. 200 sensoren, 160 ha | U35: Lessen asset-identificatie en sensorsemantiek | V35: https://www.tudelft.nl/en/2026/eemcs/tu-delft-and-argaleo-launch-complete-digital-twin-of-tu-delfts-electricity-network | W35: 52 | X35: 4.37 | Y35: v4 of eerder | Z35: nee | AA35: Twin-instantie | AB35: Schaduw of tweeling (onzeker) | AC35: Gerealiseerd | AD35: 2 Digitale schaduw | AE35: Elektriciteit | AF35: Trekker/eigenaar | AG35: B primaire bron
A36: DT-035 | B36: T | C36: Twin-instantie (NL) | D36: Liander: Gridscale X LV Insights | E36: Energie | F36: NL | G36: NL | H36: Twin-instantie | I36: Inzicht & monitoring | J36: Sturing & optimalisatie | K36: Net / nationaal systeem | L36: Schaduw | M36: Elektriciteit (LS) | N36: 3 Demonstratie/lab | O36: ADE 1.1.1-1.1.2 | P36: ADE | R36: Alliander/Liander, Siemens | S36: Trekker | T36: Contract okt. 2024 | U36: LS-net single source of truth; 10-30% extra netbenutting verwacht | V36: https://press.siemens.com/global/en/pressrelease/siemens-partners-alliander-accelerate-flexible-grid-management-netherlands | W36: 51.98 | X36: 5.91 | Y36: v4 of eerder | Z36: nee | AA36: Twin-instantie | AB36: Schaduw | AC36: Gerealiseerd | AD36: 2 Digitale schaduw | AE36: Elektriciteit | AF36: Trekker/eigenaar | AG36: B primaire bron
A37: DT-036 | B37: T | C37: Twin-instantie (NL) | D37: Liander: digitale assetinventaris (Grid Vision) | E37: Energie | F37: NL | G37: NL | H37: Bouwsteen | I37: Inzicht & monitoring | K37: Asset / installatie | L37: Model | M37: Elektriciteit | N37: 4 Operationeel | O37: ADE 1.2.3 | P37: ADE | R37: Alliander, eSmart Systems | S37: Trekker | T37: Lopend sinds 2024; ca. 60.000 stations en kasten | U37: Asset-basis voor twins | V37: https://www.esmartsystems.com/case-studies/alliander/ | W37: 51.98 | X37: 5.91 | Y37: v4 of eerder | Z37: nee | AA37: Stelsel (bouwsteen) | AB37: Model | AC37: Gerealiseerd | AD37: 1 Digitaal model | AE37: Elektriciteit | AF37: Trekker/eigenaar | AG37: B primaire bron
A38: DT-037 | B38: T | C38: Twin-instantie (NL) | D38: Stedin: netmodellen en scenario's | E38: Energie | F38: NL | G38: NL | H38: Twin-instantie | I38: Scenario & planning | K38: Net / nationaal systeem | L38: Model | M38: Elektriciteit | N38: 2 Pilot/PoC | O38: ADE 5.1 | P38: ADE | R38: Stedin | S38: Trekker | T38: In ontwikkeling; modellen nog niet gebundeld | U38: - | V38: https://stadszaken.nl/artikel/8883/een-digital-twin-van-het-energienet-in-delft-is-het-gelukt | W38: 51.92 | X38: 4.48 | Y38: v4 of eerder | Z38: nee | AA38: Twin-instantie | AB38: Model | AC38: Gerealiseerd | AD38: 1 Digitaal model | AE38: Elektriciteit | AF38: Trekker/eigenaar | AG38: C secundaire bron
A39: DT-038 | B39: T | C39: Twin-instantie (NL) | D39: TenneT: netplanning met Destination Earth-data | E39: Energie | F39: NL | G39: NL | H39: Twin-instantie | I39: Scenario & planning | J39: Voorspellen | K39: Net / nationaal systeem | L39: Model | M39: Elektriciteit | N39: 3 Demonstratie/lab | O39: EU DestinE; NPE | P39: DESTINE;NPE | R39: TenneT, ECMWF | S39: Trekker | T39: Lopend | U39: Koppeling klimaat- en energietwin | V39: https://stories.ecmwf.int/digital-twins-for-grid-operators/index.html | W39: 51.98 | X39: 5.91 | Y39: v4 of eerder | Z39: nee | AA39: Twin-instantie | AB39: Model | AC39: Gerealiseerd | AD39: 1 Digitaal model | AE39: Elektriciteit | AF39: Trekker/eigenaar | AG39: B primaire bron
A40: DT-039 | B40: T | C40: Twin-instantie (NL) | D40: Gasunie: AGMS netbesturing | E40: Energie | F40: NL | G40: NL | H40: Twin-instantie | I40: Voorspellen | J40: Sturing & optimalisatie, Onderzoek & training | K40: Net / nationaal systeem | L40: Tweeling | M40: Gas, H2, warmte, CO2 | N40: 4 Operationeel | O40: - | P40: - | R40: Gasunie, Schneider Electric | S40: Trekker | T40: Operationeel sinds 2018, uitgebreid | U40: Volwassen operationele twin buiten elektriciteit | V40: https://www.se.com/nl/nl/about-us/newsroom/news/press-releases/gasunie-digitaliseert-energienetwerk-met-agms-680f784f9e46cc8bf50e9c10/ | W40: 53.22 | X40: 6.57 | Y40: v4 of eerder | Z40: nee | AA40: Twin-instantie | AB40: Tweeling | AC40: Gerealiseerd | AD40: 5 Sturende tweeling | AE40: Gas; Waterstof; Warmte/koude (multi-commodity) | AF40: Trekker/eigenaar | AG40: B primaire bron
...

Sheet Werkhypothesen
A1: ID | B1: Thema | C1: Werkhypothese | D1: Onderbouwing (deskresearch) | E1: Initiatieven | F1: Zekerheid
A2: H01 | B2: Functies | C2: Scenario & planning is de dominante functie, verdeeld over drie schalen: wijk/hub, net/nationaal en gemeente/regio. Op asset- en gebouwniveau gaat het vrijwel altijd om inzicht of sturing. | D2: 65 van 146 initiatieven noemen scenario & planning, 40 als primaire functie. Van de 25 energie-twins en -faciliteiten met deze primaire functie zitten er 9 op wijk/hub-, 8 op net/nationaal- en 7 op gemeente/regioniveau (figuur 3). | E2: DT-029 t/m DT-033, DT-046, DT-059, DT-012, DT-015, DT-022, DT-037, DT-038 | F2: Hoog
A3: H02 | B3: Functies | C3: Functies komen in vaste paren voor. Dat wijst op twee archetypen: een plantwin (scenario + gezamenlijke besluitvorming) voor afstemming tussen partijen, en een operationele twin (inzicht + sturing) bij netbeheerders en assets. | D3: Bij 77 twin-instanties en faciliteiten zijn dit de twee meest voorkomende paren (elk 13 keer); 65 van de 77 hebben precies twee functies. | E3: DT-028, DT-031, DT-032, DT-046, DT-049, DT-035, DT-041, DT-055, DT-058, DT-120 | F3: Midden
A4: H03 | B4: Functies | C4: Sturing & optimalisatie wordt vaak beoogd maar zelden gerealiseerd. Operationeel sturende twins staan vooral buiten het elektriciteitsnet (gas, warmte, gebouwen, water). | D4: 40 initiatieven noemen sturing; primair bij 11, waarvan de meeste lab of pilot zijn. Gerealiseerd en operationeel: Gasunie AGMS (DT-039), Gradyent (DT-042), VB Optimum (DT-045) en WBL (DT-054). | E4: DT-014, DT-024, DT-039, DT-042, DT-045, DT-054, DT-055, DT-058, DT-104 | F4: Midden
A5: H04 | B5: Functies | C5: Voorspellen is als twinfunctie ondervertegenwoordigd, omdat voorspelmodellen (zoals OpenSTEF) door netbeheerders niet als twin worden gezien. | D5: Voorspellen komt 14 keer voor, primair 6 keer. OpenSTEF is bij Alliander operationeel maar staat als bouwsteen in het register. | E5: DT-069, DT-038, DT-039, DT-042, DT-056 | F5: Laag
A6: H05 | B6: Functies | C6: In de gebouwde omgeving is de twin vooral een overleginstrument, in energie vooral een rekeninstrument. Een brug tussen beide vraagt om beide functies in één toepassing. | D6: Gezamenlijke besluitvorming: 19 van 34 GO-initiatieven, 16 van 80 energie-initiatieven, 7 van 17 Energie + GO. | E6: DT-006, DT-018, DT-048, DT-090, DT-049, DT-047, DT-028 | F6: Midden
A7: H06 | B7: Overlap en aanvulling | C7: Energiehub-twins overlappen: Nederlandse initiatieven doen hetzelfde type scenario-analyse op wijk/hub-schaal met verschillende modellen, zonder zichtbaar hergebruik. | D7: Zeven NL-twins met scenario & planning op wijk/hub-schaal (DT-029, DT-030, DT-031, DT-032, DT-033, DT-046, DT-059), plus blauwdruk EIGEN (DT-078) en GO-e (DT-079). Gebruikte modellen: HOLON (DT-031, DT-032), ESDL/ETM (DT-028), eigen optimizer (DT-033), Gradyent (DT-029). | E7: DT-029, DT-030, DT-031, DT-032, DT-033, DT-046, DT-059, DT-078, DT-079 | F7: Midden
A8: H07 | B8: Overlap en aanvulling | C8: Rond de nationale systeemtwin lopen meerdere sporen die elkaar kunnen aanvullen: transportnet-simulatie (DT-015), weerdata uit Destination Earth (DT-038), het Control Room-lab (DT-014), de KIC (DT-013) en de onderzoeksinfrastructuur UTOPYS (DT-027) zijn kandidaat-deelsystemen of kennisbron voor de Nationale Faciliteit (DT-012). | D8: Vijf NL-initiatieven met scenario & planning op net/nationaal niveau (DT-012, DT-015, DT-022, DT-037, DT-038); TU Delft en TenneT zijn bij vrijwel alle betrokken. De KIC-call stelt expliciet dat de resultaten van DT-013 in DT-012 worden gebruikt; voor DT-027 is geen relatie met DT-012 gevonden. | E8: DT-012, DT-013, DT-014, DT-015, DT-022, DT-037, DT-038, DT-103, DT-027 | F8: Midden
A9: H08 | B9: Overlap en aanvulling | C9: In de gebouwde omgeving lopen twee open platformlijnen naast elkaar (Netherlands3D en Digitale Tweeling Nederland), met daarnaast commerciële platforms (Argaleo, Esri) per gemeente. | D9: DT-071 en DT-072 hebben beide inzicht & monitoring en gezamenlijke besluitvorming op gemeenteschaal; DT-034, DT-052 en DT-053 gebruiken Argaleo, DT-040 en DT-049 Esri. | E9: DT-071, DT-072, DT-075, DT-017, DT-089, DT-092, DT-034, DT-040, DT-049, DT-052, DT-053 | F9: Midden
A10: H09 | B10: Overlap en aanvulling | C10: Open rekenkernen (LF Energy) en de twinplatforms van netbeheerders vullen elkaar aan, maar zijn niet verbonden: platforms worden ingekocht, rekenkernen apart ontwikkeld. | D10: Liander koopt Gridscale X (Siemens) en assetinventaris (eSmart), terwijl Alliander Power Grid Model en OpenSTEF initieert. Buitenlandse DSO's gebruiken Envelio, Neara of Kongsberg. | E10: DT-069, DT-070, DT-035, DT-036, DT-037, DT-115, DT-120, DT-124, DT-125, DT-139 | F10: Midden
A11: H10 | B11: Overlap en aanvulling | C11: Het Normo en het Energie Dataportaal leveren de data die regionale en lokale twins nodig hebben, maar de roadmap dataproducten noemt twins niet. De vraag- en aanbodkant zijn nog niet verbonden. | D11: De roadmap van januari 2026 noemt twins niet (DT-067). Energie + GO-twins gebruiken capaciteits- en netdata (DT-049, DT-088, DT-057). | E11: DT-066, DT-067, DT-049, DT-088, DT-057, DT-028 | F11: Hoog
A12: H11 | B12: Overlap en aanvulling | C12: Afgeronde MOOI-, SBIR- en NWO-projecten hebben twin-componenten opgeleverd die niet zichtbaar worden hergebruikt. | D12: Afgerond: SynergyS (DT-016), TeSopS (DT-023), Realtime systeemwerking (DT-024), LEO (DT-056), TROEF (DT-058), EIGEN (DT-078), GO-e (DT-079). Bij geen van deze is een beheerder of vervolg vastgesteld. | E12: DT-016, DT-023, DT-024, DT-056, DT-058, DT-078, DT-079 | F12: Midden
... A30: H29 | B30: Benaderingen | C30: Holarchie kan lokale twins (woning, wijk, bedrijventerrein, hub) en de nationale systeemtwin verbinden zonder één centraal model: elke twin modelleert en balanceert eerst zijn eigen geheel en wisselt via vaste interfaces een samengevatte toestand en flexibiliteit uit met het niveau erboven. | D30: HOLON (DT-146) past holarchie toe op lokale energiesystemen; het model draait in DT-031 en DT-032. Rehtanz e.a. (2024) stellen holonische structuren voor als ICT-architectuur voor netautomatisering en flexibiliteit. De W3C Holon Graph Community Group (2026) werkt holons uit als named graphs met grenzen en projecties. Zerbst (2026) noemt een gedeelde semantische laag een voorwaarde voor bruikbare twins. Geen twin in het register is expliciet als holarchie opgezet. | E30: DT-146, DT-031, DT-032, DT-012, DT-099, DT-009 | F30: Laag

Sheet Kaders
A1: Code | B1: Kader | C1: Type | D1: Eigenaar | E1: Niveau | F1: Wat het zegt over digital twins | G1: Aantal gekoppelde initiatieven | H1: Bron
A2: NPE | B2: Nationaal Plan Energiesysteem (actualisatie 2026) | C2: Beleid | D2: Ministerie EZK/KGG | E2: NL | F2: Innovatie als randvoorwaarde voor netcongestie, weerbaarheid en autonomie; twins niet specifiek genoemd (te verifiëren in volledige tekst) | G2: =COUNTIF(Portfolio!$P$2:$P$500,"*"&A2&"*") | H2: https://energy-innovation.nl/nl/nieuws/uitdagingen-energiesysteem-vragen-om-gerichte-inzet-van-innovatie/
A3: ADE | B3: Actieagenda Digitalisering Energiesysteem | C3: Beleid / programma | D3: KGG, TNO; programmaregie Energy Innovation NL | E3: NL | F3: Actie 1.1.3 'Ontwikkel een digital twin van het elektriciteitssysteem'; twins bij planning (thema 5); 4.1.2 referentiearchitectuur (alleen data-uitwisseling); 1.1.4 eisen aan simulatie-tooling; 5.1.1 planningsmodellen; scope alleen elektriciteit | G3: =COUNTIF(Portfolio!$P$2:$P$500,"*"&A3&"*") | H3: https://www.tno.nl/nl/newsroom/2025/12/overheid-tno-topsector-energie-lanceren/
A4: NEDRA | B4: Nederlandse Energie Domein Referentie Architectuur | C4: Architectuur | D4: Energy Innovation NL (Topsector Energie) | E4: NL | F4: Digital twin als componentbouwblok; ORTESE uitgewerkt als praktijkcase (klantreis, waardeketen, bouwblokken, rollen, afspraken); koppelt aan 12+ modellen (NBility, USEF, SGAM, OpenADR, EFI/S2, HEMRM, LEAP, MSRA, DATA-X, GAIA-X, OMEGA-X) | G4: =COUNTIF(Portfolio!$P$2:$P$500,"*"&A4&"*") | H4: https://energy-innovation.nl/nl/projecten/bouwen-aan-een-robuuste-referentiearchitectuur-voor-de-energiesector/
A5: NLDT | B5: Programma Digitale Tweeling / NLDT-architectuur (nLDT) | C5: Architectuur / programma | D5: Zicht op Nederland (BZK), Geonovum, VNG, Kadaster | E5: NL | F5: Federatie van lokale twins; data, rekenmodel en visualisatie ontkoppeld; energie was al in 2021 benoemd als dataspace ('DT Energie') in het nDTFL-voorstel | G5: =COUNTIF(Portfolio!$P$2:$P$500,"*"&A5&"*") | H5: https://geonovum.github.io/NLDT-Architectuur/
A6: DSGO | B6: Digitaal Stelsel Gebouwde Omgeving | C6: Afsprakenstelsel | D6: digiGO | E6: NL | F6: Afspraken en federatieve componenten voor gebouwdata; inventarisatie federatieve componenten digitale tweeling (2022) | G6: =COUNTIF(Portfolio!$P$2:$P$500,"*"&A6&"*") | H6: https://www.digigo.nu/afsprakenstelsel/
A7: HETNORMO | B7: Afsprakenstelsel energiedata (Het Normo, Energiewet) | C7: Afsprakenstelsel | D7: Het Normo (GUE sinds 1-1-2026) | E7: NL | F7: Datalaag en toegang voor twins; roadmap dataproducten noemt twins niet | G7: =COUNTIF(Portfolio!$P$2:$P$500,"*"&A7&"*") | H7: https://data-governance-2026.reports.energiedata.nl/initiatieven-data-delen.html
A8: TSE-INNOV | B8: NL innovatie-instrumentarium (MOOI, KIC, Systeemintegratie, energiehubs, Nationaal Groeifonds) | C8: Financiering / programma | D8: RVO, NWO, Energy Innovation NL | E8: NL | F8: Financiert R&D en demonstraties; herbruikbaarheid nog geen voorwaarde | G8: =COUNTIF(Portfolio!$P$2:$P$500,"*"&A8&"*") | H8: https://energy-innovation.nl/nl/nieuws/nwo-kic-call-ontgrendel-de-kracht-van-de-digital-twin-voor-netbeheerders/
A9: SGAM | B9: Smart Grid Architecture Model | C9: Architectuur | D9: CEN-CENELEC-ETSI | E9: EU | F9: Referentiemodel (domeinen, zones, interoperabiliteitslagen) om twin-componenten te positioneren | G9: =COUNTIF(Portfolio!$P$2:$P$500,"*"&A9&"*") | H9: https://referentiearchitectuurtopsectorenergie.github.io/NEDRA/detail/afstemming/modellen/index.html
A10: EU-AP22 | B10: EU Actieplan Digitalisering Energiesysteem (2022) | C10: Beleid | D10: Europese Commissie | E10: EU | F10: Grondslag voor de digitale tweeling van het Europese elektriciteitsnet (ENTSO-E/DSO Entity) | G10: =COUNTIF(Portfolio!$P$2:$P$500,"*"&A10&"*") | H10: https://energy.ec.europa.eu/news/commission-welcomes-cooperation-between-entso-e-and-eu-dso-entity-digital-electricity-grid-twin-2022-12-20_en
A11: EU-RM26 | B11: EU Strategic Roadmap for Digitalisation and AI in Energy (juni 2026) | C11: Beleid | D11: Europese Commissie | E11: EU | F11: Actie 3: digital twin toolbox-blauwdruk ENTSO-E/DSO Entity medio 2026, best practices 2027 | G11: =COUNTIF(Portfolio!$P$2:$P$500,"*"&A11&"*") | H11: https://energy.ec.europa.eu/news/commission-presents-measures-digitalise-europes-energy-system-while-ensuring-sustainable-2026-06-03_en
A12: ENTSOE | B12: ENTSO-E / EU DSO Entity: TSO-DSO use cases en 'Towards a Federated Approach' | C12: Architectuur / samenwerking | D12: ENTSO-E, EU DSO Entity | E12: EU | F12: Vier gezamenlijke use cases; federatieprincipes; vijf volwassenheidsniveaus; vijfstappenroute | G12: =COUNTIF(Portfolio!$P$2:$P$500,"*"&A12&"*") | H12: https://www.entsoe.eu/news/2026/01/30/joint-report-on-tso-dso-digital-twin-use-cases/
A13: CEEDS | B13: Common European Energy Data Space | C13: Data-infrastructuur | D13: Europese Commissie; D4E-expertgroep | E13: EU | F13: Datalaag onder Europese energie-twins (TwinEU koppelt eraan) | G13: =COUNTIF(Portfolio!$P$2:$P$500,"*"&A13&"*") | H13: https://digital-strategy.ec.europa.eu/en/policies/digitalisation-energy
... A20: DSSC | B20: Data Spaces Support Centre Blueprint (technische en organisatorische bouwblokken voor data spaces) | C20: Architectuur | D20: Data Spaces Support Centre (Europese Commissie) | E20: EU | F20: Kapstok voor de federatieband: datamodellen, data-uitwisseling, herkomst, identiteit, trust framework, toegangs- en gebruiksbeleid, catalogus; basis voor EU-standaardisatie onder de Data Act | G20: =COUNTIF(Portfolio!$P$2:$P$500,"*"&A20&"*") | H20: https://dssc.eu/

Sheet Bouwstenen
A1: Code | B1: Bouwsteen | C1: Type | D1: Laag | E1: Beheer | F1: Open source / standaard | G1: Domein | H1: Rol in een twin | I1: Aantal gekoppelde initiatieven | J1: Bron
A2: BS-ESDL | B2: ESDL (+ MapEditor, ESSIM) | C2: Systeemmodel / taal | D2: Semantiek & data | E2: TNO, Quintel, community | F2: Open source | G2: Energie (systeem) | H2: Integrale beschrijving energiesysteem; koppeltaal tussen modellen | I2: =COUNTIF(Portfolio!$Q$2:$Q$500,"*"&A2&"*") | J2: https://www.esdl.nl/en/
A3: BS-ETM | B3: Energy Transition Model | C3: Rekenmodel | D3: Rekenmodel | E3: Quintel | F3: Open source | G3: Energie (systeem) | H3: Scenarioberekening (o.a. ORTESE, RES) | I3: =COUNTIF(Portfolio!$Q$2:$Q$500,"*"&A3&"*") | J3: https://energytransitionmodel.com/
A4: BS-HOLON | B4: HOLON-model (ZEnMo) | C4: Rekenmodel | D4: Rekenmodel | E4: ZEnMo, TU/e | F4: Open source (te verifiëren) | G4: Energie (lokaal) | H4: Simulatie bedrijventerreinen en energiehubs | I4: =COUNTIF(Portfolio!$Q$2:$Q$500,"*"&A4&"*") | J4: https://www.drechtstedenenergie.nl/digitaltwindrechtsteden
A5: BS-CIM | B5: IEC CIM / CGMES | C5: Informatiemodel | D5: Semantiek & data | E5: IEC TC57, ENTSO-E | F5: Open standaard | G5: Elektriciteit | H5: Netmodel, topologie en assets; basis grid-twins | I5: =COUNTIF(Portfolio!$Q$2:$Q$500,"*"&A5&"*") | J5: https://www.entsoe.eu/data/cim/cim-for-grid-models-exchange/
A6: BS-NBILITY | B6: NBility | C6: Bedrijfsmodel | D6: Semantiek & data | E6: Netbeheer Nederland | F6: Open | G6: Elektriciteit, gas | H6: Bedrijfsobjecten netbeheer | I6: =COUNTIF(Portfolio!$Q$2:$Q$500,"*"&A6&"*") | J6: https://nbility.netbeheernederland.nl/
A7: BS-IEC81346 | B7: IEC 81346 / RDS-PP | C7: Identificatiestandaard | D7: Semantiek & data | E7: IEC | F7: Standaard | G7: Assets | H7: Eenduidige asset-identificatie | I7: =COUNTIF(Portfolio!$Q$2:$Q$500,"*"&A7&"*") | J7: https://webstore.iec.ch/en/publication/64021
A8: BS-IEC61850 | B8: IEC 61850 | C8: Communicatiestandaard | D8: Semantiek & data | E8: IEC | F8: Standaard | G8: Elektriciteit (stations) | H8: Stationsconfiguratie en -communicatie; basis voor station-twins (GRID-PRO, OET, CoMPAS) | I8: =COUNTIF(Portfolio!$Q$2:$Q$500,"*"&A8&"*") | J8: https://lfenergy.org/our-projects
A9: BS-SAREF | B9: SAREF | C9: Ontologie | D9: Semantiek & data | E9: ETSI | F9: Open standaard | G9: Gebouw, apparaten | H9: Achter-de-meter en gebouw-twins | I9: =COUNTIF(Portfolio!$Q$2:$Q$500,"*"&A9&"*") | J9: https://saref.etsi.org/
A10: BS-USEF | B10: USEF / Shapeshifter (UFTP) | C10: Marktmodel / protocol | D10: Afspraken & protocol | E10: USEF, LF Energy | F10: Open source | G10: Elektriciteit (flex) | H10: Flexibiliteitsuitwisseling DSO-aggregator | I10: =COUNTIF(Portfolio!$Q$2:$Q$500,"*"&A10&"*") | J10: https://lfenergy.org/our-projects
A11: BS-S2 | B11: EFI / S2 (EN 50491-12-2) | C11: Protocol | D11: Afspraken & protocol | E11: FAN, CENELEC | F11: Open standaard | G11: Gebouw, apparaten | H11: Flexibiliteit van apparaten richting EMS | I11: =COUNTIF(Portfolio!$Q$2:$Q$500,"*"&A11&"*") | J11: https://referentiearchitectuurtopsectorenergie.github.io/NEDRA/detail/afstemming/modellen/index.html
A12: BS-OPENADR | B12: OpenADR (openLEADR) | C12: Protocol | D12: Afspraken & protocol | E12: OpenADR Alliance, LF Energy | F12: Open standaard | G12: Elektriciteit (vraagrespons) | H12: Vraagresponssignalen | I12: =COUNTIF(Portfolio!$Q$2:$Q$500,"*"&A12&"*") | J12: https://lfenergy.org/our-projects
A13: BS-ISHARE | B13: iSHARE | C13: Trust framework | D13: Trust & afspraken | E13: iSHARE Foundation | F13: Open | G13: Generiek | H13: Identificatie, authenticatie, autorisatie bij datadelen | I13: =COUNTIF(Portfolio!$Q$2:$Q$500,"*"&A13&"*") | J13: https://ishare.eu/
... A41: BS-HGA | B41: Holonic Graph Architecture (W3C Holon Graph Community Group) | C41: Architectuurpatroon (specificatie in ontwikkeling) | D41: Semantiek & data | E41: W3C Holon Graph Community Group | F41: Open (community group, nog geen standaard) | G41: Generiek | H41: Holon als named graph met eventlog, grenzen (SHACL) en projecties; kandidaat voor de semantische en federatieve laag van twins | I41: =COUNTIF(Portfolio!$Q$2:$Q$500,"*"&A41&"*") | J41: https://www.w3.org/community/holon/

Sheet Relaties
A1: Van (ID) | B1: Van (naam) | C1: Relatie | D1: Naar (ID/code) | E1: Naar (naam) | F1: Toelichting | G1: Bron
A2: DT-001 | B2: Nationaal Plan Energiesysteem (NPE), actualisatie 2026 | C2: sluit aan op kader | D2: NPE | E2: Nationaal Plan Energiesysteem (actualisatie 2026)
A3: DT-002 | B3: Actieagenda Digitalisering Energiesysteem (ADE) | C3: sluit aan op kader | D3: ADE | E3: Actieagenda Digitalisering Energiesysteem
A4: DT-002 | B4: Actieagenda Digitalisering Energiesysteem (ADE) | C4: sluit aan op kader | D4: NPE | E4: Nationaal Plan Energiesysteem (actualisatie 2026)
A5: DT-003 | B5: NEDRA: Nederlandse Energie Domein Referentie Architectuur | C5: sluit aan op kader | D5: NEDRA | E5: Nederlandse Energie Domein Referentie Architectuur
